Workbook

Sheet Employee data
A1: Employee_ID | B1: Name | C1: Department | D1: Role | E1: Hire_Date | F1: Contract_Type | G1: Shift_Pattern | H1: Base_Pay | I1: Overtime_Rate
A2: 1 | B2: Jay Kim | C2: Welding | D2: Technician | E2: 45216 | F2: Permanent | G2: Afternoon | H2: 2603 | I2: 24.4
A3: 2 | B3: Matthew Smith | C3: Logistics | D3: Operator | E3: 44956 | F3: Temporary | G3: Night | H3: 3172 | I3: 29.74
A4: 3 | B4: Sheri Davila | C4: Logistics | D4: Supervisor | E4: 45669 | F4: Permanent | G4: Morning | H4: 2795 | I4: 26.2
A5: 4 | B5: Ruth Mathis | C5: Logistics | D5: Engineer | E5: 45210 | F5: Contract | G5: Night | H5: 2409 | I5: 22.58
A6: 5 | B6: Amy Terry | C6: Welding | D6: Inspector | E6: 45021 | F6: Temporary | G6: Night | H6: 3700 | I6: 34.69
A7: 6 | B7: Michael Washington | C7: Machining | D7: Engineer | E7: 44271 | F7: Permanent | G7: Afternoon | H7: 3331 | I7: 31.23
A8: 7 | B8: James Carroll | C8: Quality | D8: Operator | E8: 44851 | F8: Contract | G8: Afternoon | H8: 2945 | I8: 27.61
A9: 8 | B9: Angela Newton DVM | C9: Quality | D9: Supervisor | E9: 44281 | F9: Temporary | G9: Night | H9: 2259 | I9: 21.18
A10: 9 | B10: Daniel Guzman | C10: Quality | D10: Operator | E10: 45142 | F10: Contract | G10: Night | H10: 2275 | I10: 21.33
A11: 10 | B11: Sarah Weber | C11: Assembly | D11: Operator | E11: 44941 | F11: Permanent | G11: Afternoon | H11: 2344 | I11: 21.98
A12: 11 | B12: Stacy Wells | C12: Welding | D12: Engineer | E12: 45708 | F12: Contract | G12: Night | H12: 3935 | I12: 36.89
A13: 12 | B13: Kristen Marsh | C13: Welding | D13: Technician | E13: 45319 | F13: Temporary | G13: Night | H13: 3394 | I13: 31.82
... A301: 300 | B301: James Simpson | C301: Quality | D301: Inspector | E301: 44539 | F301: Contract | G301: Night | H301: 3113 | I301: 29.18

Sheet Attendance records
A1: Date | B1: Date(Month) | C1: Employee_ID | D1: Scheduled_Shift | E1: Status | F1: Absent Flag | G1: Scheduled Flag
A2: 45839 | B2: =TEXT(A2,"YYYY-MM") -> 2025-07 | C2: 1 | D2: Afternoon | E2: Present | F2: =IF(E2="Absent",1,0) -> 0 | G2: =IF(D2<>"",1,0) -> 1
A3: 45839 | B3: =TEXT(A3,"YYYY-MM") -> 2025-07 | C3: 2 | D3: Night | E3: Present | F3: =IF(E3="Absent",1,0) -> 0 | G3: =IF(D3<>"",1,0) -> 1
A4: 45839 | B4: =TEXT(A4,"YYYY-MM") -> 2025-07 | C4: 3 | D4: Morning | E4: Present | F4: =IF(E4="Absent",1,0) -> 0 | G4: =IF(D4<>"",1,0) -> 1
A5: 45839 | B5: =TEXT(A5,"YYYY-MM") -> 2025-07 | C5: 4 | D5: Night | E5: Present | F5: =IF(E5="Absent",1,0) -> 0 | G5: =IF(D5<>"",1,0) -> 1
A6: 45839 | B6: =TEXT(A6,"YYYY-MM") -> 2025-07 | C6: 5 | D6: Night | E6: Present | F6: =IF(E6="Absent",1,0) -> 0 | G6: =IF(D6<>"",1,0) -> 1
A7: 45839 | B7: =TEXT(A7,"YYYY-MM") -> 2025-07 | C7: 6 | D7: Afternoon | E7: Present | F7: =IF(E7="Absent",1,0) -> 0 | G7: =IF(D7<>"",1,0) -> 1
A8: 45839 | B8: =TEXT(A8,"YYYY-MM") -> 2025-07 | C8: 7 | D8: Afternoon | E8: Present | F8: =IF(E8="Absent",1,0) -> 0 | G8: =IF(D8<>"",1,0) -> 1
A9: 45839 | B9: =TEXT(A9,"YYYY-MM") -> 2025-07 | C9: 8 | D9: Night | E9: Present | F9: =IF(E9="Absent",1,0) -> 0 | G9: =IF(D9<>"",1,0) -> 1
A10: 45839 | B10: =TEXT(A10,"YYYY-MM") -> 2025-07 | C10: 9 | D10: Night | E10: Present | F10: =IF(E10="Absent",1,0) -> 0 | G10: =IF(D10<>"",1,0) -> 1
A11: 45839 | B11: =TEXT(A11,"YYYY-MM") -> 2025-07 | C11: 10 | D11: Afternoon | E11: Present | F11: =IF(E11="Absent",1,0) -> 0 | G11: =IF(D11<>"",1,0) -> 1
A12: 45839 | B12: =TEXT(A12,"YYYY-MM") -> 2025-07 | C12: 11 | D12: Night | E12: Present | F12: =IF(E12="Absent",1,0) -> 0 | G12: =IF(D12<>"",1,0) -> 1
A13: 45839 | B13: =TEXT(A13,"YYYY-MM") -> 2025-07 | C13: 12 | D13: Night | E13: Present | F13: =IF(E13="Absent",1,0) -> 0 | G13: =IF(D13<>"",1,0) -> 1
... A19801: 45930 | B19801: =TEXT(A19801,"YYYY-MM") -> 2025-09 | C19801: 300 | D19801: Night | E19801: Late | F19801: =IF(E19801="Absent",1,0) -> 0 | G19801: =IF(D19801<>"",1,0) -> 1
A19802: 45931 | B19802: 2025-10 | C19802: 1 | D19802: Morning | E19802: Absent | F19802: 1 | G19802: 1

Sheet Overtime Records
A1: Date | B1: Date(Month) | C1: Employee_ID | D1: Overtime_Hours | E1: Reason | F1: Overtime_Rate | G1: Overtime_Cost
A2: 45897 | B2: =TEXT(A2,"yyyy-mm") -> 2025-08 | C2: 1 | D2: 3 | E2: Training | F2: 24.4 | G2: 73.2
A3: 45912 | B3: =TEXT(A3,"yyyy-mm") -> 2025-09 | C3: 1 | D3: 4 | E3: Production | F3: 24.4 | G3: 97.6
A4: 45866 | B4: =TEXT(A4,"yyyy-mm") -> 2025-07 | C4: 2 | D4: 2.9 | E4: Training | F4: 29.74 | G4: 86.246
A5: 45888 | B5: =TEXT(A5,"yyyy-mm") -> 2025-08 | C5: 2 | D5: 3.1 | E5: Training | F5: 29.74 | G5: 92.194
A6: 45893 | B6: =TEXT(A6,"yyyy-mm") -> 2025-08 | C6: 2 | D6: 3.2 | E6: Production | F6: 29.74 | G6: 95.168
A7: 45895 | B7: =TEXT(A7,"yyyy-mm") -> 2025-08 | C7: 2 | D7: 7.2 | E7: Training | F7: 29.74 | G7: 214.128
A8: 45923 | B8: =TEXT(A8,"yyyy-mm") -> 2025-09 | C8: 2 | D8: 2.3 | E8: Training | F8: 29.74 | G8: 68.402
A9: 45928 | B9: =TEXT(A9,"yyyy-mm") -> 2025-09 | C9: 2 | D9: 4.9 | E9: Production | F9: 29.74 | G9: 145.726
A10: 45844 | B10: =TEXT(A10,"yyyy-mm") -> 2025-07 | C10: 3 | D10: 4.4 | E10: Production | F10: 26.2 | G10: 115.28
A11: 45870 | B11: =TEXT(A11,"yyyy-mm") -> 2025-08 | C11: 3 | D11: 1.8 | E11: Cover Absence | F11: 26.2 | G11: 47.16
A12: 45883 | B12: =TEXT(A12,"yyyy-mm") -> 2025-08 | C12: 3 | D12: 2.6 | E12: Cover Absence | F12: 26.2 | G12: 68.12
A13: 45882 | B13: =TEXT(A13,"yyyy-mm") -> 2025-08 | C13: 3 | D13: 1.3 | E13: Cover Absence | F13: 26.2 | G13: 34.06
... A1828: 45890 | B1828: =TEXT(A1828,"yyyy-mm") -> 2025-08 | C1828: 300 | D1828: 5.2 | E1828: Production | F1828: 29.18 | G1828: 151.736

Sheet Summary Report
A1: Employee ID | B1: Name | C1: Date(month) | D1: Department | E1: Role | F1: Base Pay | G1: Overtime Rate | H1: Scheduled days | I1: Days Absent | J1: Overtime hours | K1: Overtime cost | L1: Absenteeism rate%
A2: 1 | B2: Jay Kim | C2: ='data dictionary'!$B$2 -> 2025-07 | D2: Welding | E2: Technician | F2: 2603 | G2: 24.4 | H2: ='data dictionary'!C$2 -> 23 | I2: =SUMIFS('Attendance records'!F:F,'Attendance records'!C:C,'Summary Report'!A2,'Attendance records'!B:B,'Summary Report'!C2) -> 2 | J2: =SUMIFS('Overtime Records'!D:D,'Overtime Records'!C:C,'Summary Report'!A2,'Overtime Records'!B:B,'Summary Report'!C2) -> 0 | K2: =J2*G2 -> 0 | L2: =I2/H2 -> 0.086956522
A3: 2 | B3: Matthew Smith | C3: ='data dictionary'!$B$2 -> 2025-07 | D3: Logistics | E3: Operator | F3: 3172 | G3: 29.74 | H3: ='data dictionary'!C$2 -> 23 | I3: =SUMIFS('Attendance records'!F:F,'Attendance records'!C:C,'Summary Report'!A3,'Attendance records'!B:B,'Summary Report'!C3) -> 2 | J3: =SUMIFS('Overtime Records'!D:D,'Overtime Records'!C:C,'Summary Report'!A3,'Overtime Records'!B:B,'Summary Report'!C3) -> 2.9 | K3: =J3*G3 -> 86.246 | L3: =I3/H3 -> 0.086956522
A4: 3 | B4: Sheri Davila | C4: ='data dictionary'!$B$2 -> 2025-07 | D4: Logistics | E4: Supervisor | F4: 2795 | G4: 26.2 | H4: ='data dictionary'!C$2 -> 23 | I4: =SUMIFS('Attendance records'!F:F,'Attendance records'!C:C,'Summary Report'!A4,'Attendance records'!B:B,'Summary Report'!C4) -> 0 | J4: =SUMIFS('Overtime Records'!D:D,'Overtime Records'!C:C,'Summary Report'!A4,'Overtime Records'!B:B,'Summary Report'!C4) -> 4.4 | K4: =J4*G4 -> 115.28 | L4: =I4/H4 -> 0
A5: 4 | B5: Ruth Mathis | C5: ='data dictionary'!$B$2 -> 2025-07 | D5: Logistics | E5: Engineer | F5: 2409 | G5: 22.58 | H5: ='data dictionary'!C$2 -> 23 | I5: =SUMIFS('Attendance records'!F:F,'Attendance records'!C:C,'Summary Report'!A5,'Attendance records'!B:B,'Summary Report'!C5) -> 2 | J5: =SUMIFS('Overtime Records'!D:D,'Overtime Records'!C:C,'Summary Report'!A5,'Overtime Records'!B:B,'Summary Report'!C5) -> 0 | K5: =J5*G5 -> 0 | L5: =I5/H5 -> 0.086956522
A6: 5 | B6: Amy Terry | C6: ='data dictionary'!$B$2 -> 2025-07 | D6: Welding | E6: Inspector | F6: 3700 | G6: 34.69 | H6: ='data dictionary'!C$2 -> 23 | I6: =SUMIFS('Attendance records'!F:F,'Attendance records'!C:C,'Summary Report'!A6,'Attendance records'!B:B,'Summary Report'!C6) -> 1 | J6: =SUMIFS('Overtime Records'!D:D,'Overtime Records'!C:C,'Summary Report'!A6,'Overtime Records'!B:B,'Summary Report'!C6) -> 13.9 | K6: =J6*G6 -> 482.191 | L6: =I6/H6 -> 0.043478261
A7: 6 | B7: Michael Washington | C7: ='data dictionary'!$B$2 -> 2025-07 | D7: Machining | E7: Engineer | F7: 3331 | G7: 31.23 | H7: ='data dictionary'!C$2 -> 23 | I7: =SUMIFS('Attendance records'!F:F,'Attendance records'!C:C,'Summary Report'!A7,'Attendance records'!B:B,'Summary Report'!C7) -> 2 | J7: =SUMIFS('Overtime Records'!D:D,'Overtime Records'!C:C,'Summary Report'!A7,'Overtime Records'!B:B,'Summary Report'!C7) -> 6.3 | K7: =J7*G7 -> 196.749 | L7: =I7/H7 -> 0.086956522
A8: 7 | B8: James Carroll | C8: ='data dictionary'!$B$2 -> 2025-07 | D8: Quality | E8: Operator | F8: 2945 | G8: 27.61 | H8: ='data dictionary'!C$2 -> 23 | I8: =SUMIFS('Attendance records'!F:F,'Attendance records'!C:C,'Summary Report'!A8,'Attendance records'!B:B,'Summary Report'!C8) -> 0 | J8: =SUMIFS('Overtime Records'!D:D,'Overtime Records'!C:C,'Summary Report'!A8,'Overtime Records'!B:B,'Summary Report'!C8) -> 19.6 | K8: =J8*G8 -> 541.156 | L8: =I8/H8 -> 0
A9: 8 | B9: Angela Newton DVM | C9: ='data dictionary'!$B$2 -> 2025-07 | D9: Quality | E9: Supervisor | F9: 2259 | G9: 21.18 | H9: ='data dictionary'!C$2 -> 23 | I9: =SUMIFS('Attendance records'!F:F,'Attendance records'!C:C,'Summary Report'!A9,'Attendance records'!B:B,'Summary Report'!C9) -> 1 | J9: =SUMIFS('Overtime Records'!D:D,'Overtime Records'!C:C,'Summary Report'!A9,'Overtime Records'!B:B,'Summary Report'!C9) -> 17.6 | K9: =J9*G9 -> 372.768 | L9: =I9/H9 -> 0.043478261
A10: 9 | B10: Daniel Guzman | C10: ='data dictionary'!$B$2 -> 2025-07 | D10: Quality | E10: Operator | F10: 2275 | G10: 21.33 | H10: ='data dictionary'!C$2 -> 23 | I10: =SUMIFS('Attendance records'!F:F,'Attendance records'!C:C,'Summary Report'!A10,'Attendance records'!B:B,'Summary Report'!C10) -> 1 | J10: =SUMIFS('Overtime Records'!D:D,'Overtime Records'!C:C,'Summary Report'!A10,'Overtime Records'!B:B,'Summary Report'!C10) -> 0 | K10: =J10*G10 -> 0 | L10: =I10/H10 -> 0.043478261
A11: 10 | B11: Sarah Weber | C11: ='data dictionary'!$B$2 -> 2025-07 | D11: Assembly | E11: Operator | F11: 2344 | G11: 21.98 | H11: ='data dictionary'!C$2 -> 23 | I11: =SUMIFS('Attendance records'!F:F,'Attendance records'!C:C,'Summary Report'!A11,'Attendance records'!B:B,'Summary Report'!C11) -> 2 | J11: =SUMIFS('Overtime Records'!D:D,'Overtime Records'!C:C,'Summary Report'!A11,'Overtime Records'!B:B,'Summary Report'!C11) -> 9.9 | K11: =J11*G11 -> 217.602 | L11: =I11/H11 -> 0.086956522
A12: 11 | B12: Stacy Wells | C12: ='data dictionary'!$B$2 -> 2025-07 | D12: Welding | E12: Engineer | F12: 3935 | G12: 36.89 | H12: ='data dictionary'!C$2 -> 23 | I12: =SUMIFS('Attendance records'!F:F,'Attendance records'!C:C,'Summary Report'!A12,'Attendance records'!B:B,'Summary Report'!C12) -> 4 | J12: =SUMIFS('Overtime Records'!D:D,'Overtime Records'!C:C,'Summary Report'!A12,'Overtime Records'!B:B,'Summary Report'!C12) -> 2.4 | K12: =J12*G12 -> 88.536 | L12: =I12/H12 -> 0.17391304
A13: 12 | B13: Kristen Marsh | C13: ='data dictionary'!$B$2 -> 2025-07 | D13: Welding | E13: Technician | F13: 3394 | G13: 31.82 | H13: ='data dictionary'!C$2 -> 23 | I13: =SUMIFS('Attendance records'!F:F,'Attendance records'!C:C,'Summary Report'!A13,'Attendance records'!B:B,'Summary Report'!C13) -> 2 | J13: =SUMIFS('Overtime Records'!D:D,'Overtime Records'!C:C,'Summary Report'!A13,'Overtime Records'!B:B,'Summary Report'!C13) -> 4.1 | K13: =J13*G13 -> 130.462 | L13: =I13/H13 -> 0.086956522
... A301: 300 | B301: James Simpson | C301: ='data dictionary'!$B$2 -> 2025-07 | D301: Quality | E301: Inspector | F301: 3113 | G301: 29.18 | H301: ='data dictionary'!C$2 -> 23 | I301: =SUMIFS('Attendance records'!F:F,'Attendance records'!C:C,'Summary Report'!A301,'Attendance records'!B:B,'Summary Report'!C301) -> 0 | J301: =SUMIFS('Overtime Records'!D:D,'Overtime Records'!C:C,'Summary Report'!A301,'Overtime Records'!B:B,'Summary Report'!C301) -> 9.4 | K301: =J301*G301 -> 274.292 | L301: =I301/H301 -> 0
A303: 1 | B303: Jay Kim | C303: ='data dictionary'!$B$3 -> 2025-08 | D303: Welding | E303: Technician | F303: 2603 | G303: 24.4 | H303: ='data dictionary'!C$3 -> 21 | I303: =SUMIFS('Attendance records'!F:F,'Attendance records'!C:C,'Summary Report'!A303,'Attendance records'!B:B,'Summary Report'!C303) -> 1 | J303: =SUMIFS('Overtime Records'!D:D,'Overtime Records'!C:C,'Summary Report'!A303,'Overtime Records'!B:B,'Summary Report'!C303) -> 3 | K303: =J303*G303 -> 73.2 | L303: =I303/H303 -> 0.047619048
A304: 2 | B304: Matthew Smith | C304: ='data dictionary'!$B$3 -> 2025-08 | D304: Logistics | E304: Operator | F304: 3172 | G304: 29.74 | H304: ='data dictionary'!C$3 -> 21 | I304: =SUMIFS('Attendance records'!F:F,'Attendance records'!C:C,'Summary Report'!A304,'Attendance records'!B:B,'Summary Report'!C304) -> 2 | J304: =SUMIFS('Overtime Records'!D:D,'Overtime Records'!C:C,'Summary Report'!A304,'Overtime Records'!B:B,'Summary Report'!C304) -> 13.5 | K304: =J304*G304 -> 401.49 | L304: =I304/H304 -> 0.095238095
A305: 3 | B305: Sheri Davila | C305: ='data dictionary'!$B$3 -> 2025-08 | D305: Logistics | E305: Supervisor | F305: 2795 | G305: 26.2 | H305: ='data dictionary'!C$3 -> 21 | I305: =SUMIFS('Attendance records'!F:F,'Attendance records'!C:C,'Summary Report'!A305,'Attendance records'!B:B,'Summary Report'!C305) -> 1 | J305: =SUMIFS('Overtime Records'!D:D,'Overtime Records'!C:C,'Summary Report'!A305,'Overtime Records'!B:B,'Summary Report'!C305) -> 5.7 | K305: =J305*G305 -> 149.34 | L305: =I305/H305 -> 0.047619048
A306: 4 | B306: Ruth Mathis | C306: ='data dictionary'!$B$3 -> 2025-08 | D306: Logistics | E306: Engineer | F306: 2409 | G306: 22.58 | H306: ='data dictionary'!C$3 -> 21 | I306: =SUMIFS('Attendance records'!F:F,'Attendance records'!C:C,'Summary Report'!A306,'Attendance records'!B:B,'Summary Report'!C306) -> 3 | J306: =SUMIFS('Overtime Records'!D:D,'Overtime Records'!C:C,'Summary Report'!A306,'Overtime Records'!B:B,'Summary Report'!C306) -> 15.6 | K306: =J306*G306 -> 352.248 | L306: =I306/H306 -> 0.14285714
A307: 5 | B307: Amy Terry | C307: ='data dictionary'!$B$3 -> 2025-08 | D307: Welding | E307: Inspector | F307: 3700 | G307: 34.69 | H307: ='data dictionary'!C$3 -> 21 | I307: =SUMIFS('Attendance records'!F:F,'Attendance records'!C:C,'Summary Report'!A307,'Attendance records'!B:B,'Summary Report'!C307) -> 3 | J307: =SUMIFS('Overtime Records'!D:D,'Overtime Records'!C:C,'Summary Report'!A307,'Overtime Records'!B:B,'Summary Report'!C307) -> 2.9 | K307: =J307*G307 -> 100.601 | L307: =I307/H307 -> 0.14285714
A308: 6 | B308: Michael Washington | C308: ='data dictionary'!$B$3 -> 2025-08 | D308: Machining | E308: Engineer | F308: 3331 | G308: 31.23 | H308: ='data dictionary'!C$3 -> 21 | I308: =SUMIFS('Attendance records'!F:F,'Attendance records'!C:C,'Summary Report'!A308,'Attendance records'!B:B,'Summary Report'!C308) -> 1 | J308: =SUMIFS('Overtime Records'!D:D,'Overtime Records'!C:C,'Summary Report'!A308,'Overtime Records'!B:B,'Summary Report'!C308) -> 17.7 | K308: =J308*G308 -> 552.771 | L308: =I308/H308 -> 0.047619048
A309: 7 | B309: James Carroll | C309: ='data dictionary'!$B$3 -> 2025-08 | D309: Quality | E309: Operator | F309: 2945 | G309: 27.61 | H309: ='data dictionary'!C$3 -> 21 | I309: =SUMIFS('Attendance records'!F:F,'Attendance records'!C:C,'Summary Report'!A309,'Attendance records'!B:B,'Summary Report'!C309) -> 0 | J309: =SUMIFS('Overtime Records'!D:D,'Overtime Records'!C:C,'Summary Report'!A309,'Overtime Records'!B:B,'Summary Report'!C309) -> 10.7 | K309: =J309*G309 -> 295.427 | L309: =I309/H309 -> 0
A310: 8 | B310: Angela Newton DVM | C310: ='data dictionary'!$B$3 -> 2025-08 | D310: Quality | E310: Supervisor | F310: 2259 | G310: 21.18 | H310: ='data dictionary'!C$3 -> 21 | I310: =SUMIFS('Attendance records'!F:F,'Attendance records'!C:C,'Summary Report'!A310,'Attendance records'!B:B,'Summary Report'!C310) -> 1 | J310: =SUMIFS('Overtime Records'!D:D,'Overtime Records'!C:C,'Summary Report'!A310,'Overtime Records'!B:B,'Summary Report'!C310) -> 2.4 | K310: =J310*G310 -> 50.832 | L310: =I310/H310 -> 0.047619048
A311: 9 | B311: Daniel Guzman | C311: ='data dictionary'!$B$3 -> 2025-08 | D311: Quality | E311: Operator | F311: 2275 | G311: 21.33 | H311: ='data dictionary'!C$3 -> 21 | I311: =SUMIFS('Attendance records'!F:F,'Attendance records'!C:C,'Summary Report'!A311,'Attendance records'!B:B,'Summary Report'!C311) -> 1 | J311: =SUMIFS('Overtime Records'!D:D,'Overtime Records'!C:C,'Summary Report'!A311,'Overtime Records'!B:B,'Summary Report'!C311) -> 2.2 | K311: =J311*G311 -> 46.926 | L311: =I311/H311 -> 0.047619048
A312: 10 | B312: Sarah Weber | C312: ='data dictionary'!$B$3 -> 2025-08 | D312: Assembly | E312: Operator | F312: 2344 | G312: 21.98 | H312: ='data dictionary'!C$3 -> 21 | I312: =SUMIFS('Attendance records'!F:F,'Attendance records'!C:C,'Summary Report'!A312,'Attendance records'!B:B,'Summary Report'!C312) -> 1 | J312: =SUMIFS('Overtime Records'!D:D,'Overtime Records'!C:C,'Summary Report'!A312,'Overtime Records'!B:B,'Summary Report'!C312) -> 6.4 | K312: =J312*G312 -> 140.672 | L312: =I312/H312 -> 0.047619048
A313: 11 | B313: Stacy Wells | C313: ='data dictionary'!$B$3 -> 2025-08 | D313: Welding | E313: Engineer | F313: 3935 | G313: 36.89 | H313: ='data dictionary'!C$3 -> 21 | I313: =SUMIFS('Attendance records'!F:F,'Attendance records'!C:C,'Summary Report'!A313,'Attendance records'!B:B,'Summary Report'!C313) -> 2 | J313: =SUMIFS('Overtime Records'!D:D,'Overtime Records'!C:C,'Summary Report'!A313,'Overtime Records'!B:B,'Summary Report'!C313) -> 5.4 | K313: =J313*G313 -> 199.206 | L313: =I313/H313 -> 0.095238095
A314: 12 | B314: Kristen Marsh | C314: ='data dictionary'!$B$3 -> 2025-08 | D314: Welding | E314: Technician | F314: 3394 | G314: 31.82 | H314: ='data dictionary'!C$3 -> 21 | I314: =SUMIFS('Attendance records'!F:F,'Attendance records'!C:C,'Summary Report'!A314,'Attendance records'!B:B,'Summary Report'!C314) -> 4 | J314: =SUMIFS('Overtime Records'!D:D,'Overtime Records'!C:C,'Summary Report'!A314,'Overtime Records'!B:B,'Summary Report'!C314) -> 0 | K314: =J314*G314 -> 0 | L314: =I314/H314 -> 0.19047619
... A602: 300 | B602: James Simpson | C602: ='data dictionary'!$B$3 -> 2025-08 | D602: Quality | E602: Inspector | F602: 3113 | G602: 29.18 | H602: ='data dictionary'!C$3 -> 21 | I602: =SUMIFS('Attendance records'!F:F,'Attendance records'!C:C,'Summary Report'!A602,'Attendance records'!B:B,'Summary Report'!C602) -> 0 | J602: =SUMIFS('Overtime Records'!D:D,'Overtime Records'!C:C,'Summary Report'!A602,'Overtime Records'!B:B,'Summary Report'!C602) -> 5.2 | K602: =J602*G602 -> 151.736 | L602: =I602/H602 -> 0
A604: 1 | B604: Jay Kim | C604: ='data dictionary'!$B$4 -> 2025-09 | D604: Welding | E604: Technician | F604: 2603 | G604: 24.4 | H604: ='data dictionary'!C$4 -> 22 | I604: =SUMIFS('Attendance records'!F:F,'Attendance records'!C:C,'Summary Report'!A604,'Attendance records'!B:B,'Summary Report'!C604) -> 0 | J604: =SUMIFS('Overtime Records'!D:D,'Overtime Records'!C:C,'Summary Report'!A604,'Overtime Records'!B:B,'Summary Report'!C604) -> 4 | K604: =J604*G604 -> 97.6 | L604: =I604/H604 -> 0
A605: 2 | B605: Matthew Smith | C605: ='data dictionary'!$B$4 -> 2025-09 | D605: Logistics | E605: Operator | F605: 3172 | G605: 29.74 | H605: ='data dictionary'!C$4 -> 22 | I605: =SUMIFS('Attendance records'!F:F,'Attendance records'!C:C,'Summary Report'!A605,'Attendance records'!B:B,'Summary Report'!C605) -> 1 | J605: =SUMIFS('Overtime Records'!D:D,'Overtime Records'!C:C,'Summary Report'!A605,'Overtime Records'!B:B,'Summary Report'!C605) -> 7.2 | K605: =J605*G605 -> 214.128 | L605: =I605/H605 -> 0.045454545
A606: 3 | B606: Sheri Davila | C606: ='data dictionary'!$B$4 -> 2025-09 | D606: Logistics | E606: Supervisor | F606: 2795 | G606: 26.2 | H606: ='data dictionary'!C$4 -> 22 | I606: =SUMIFS('Attendance records'!F:F,'Attendance records'!C:C,'Summary Report'!A606,'Attendance records'!B:B,'Summary Report'!C606) -> 2 | J606: =SUMIFS('Overtime Records'!D:D,'Overtime Records'!C:C,'Summary Report'!A606,'Overtime Records'!B:B,'Summary Report'!C606) -> 1.8 | K606: =J606*G606 -> 47.16 | L606: =I606/H606 -> 0.090909091
A607: 4 | B607: Ruth Mathis | C607: ='data dictionary'!$B$4 -> 2025-09 | D607: Logistics | E607: Engineer | F607: 2409 | G607: 22.58 | H607: ='data dictionary'!C$4 -> 22 | I607: =SUMIFS('Attendance records'!F:F,'Attendance records'!C:C,'Summary Report'!A607,'Attendance records'!B:B,'Summary Report'!C607) -> 1 | J607: =SUMIFS('Overtime Records'!D:D,'Overtime Records'!C:C,'Summary Report'!A607,'Overtime Records'!B:B,'Summary Report'!C607) -> 10.9 | K607: =J607*G607 -> 246.122 | L607: =I607/H607 -> 0.045454545
A608: 5 | B608: Amy Terry | C608: ='data dictionary'!$B$4 -> 2025-09 | D608: Welding | E608: Inspector | F608: 3700 | G608: 34.69 | H608: ='data dictionary'!C$4 -> 22 | I608: =SUMIFS('Attendance records'!F:F,'Attendance records'!C:C,'Summary Report'!A608,'Attendance records'!B:B,'Summary Report'!C608) -> 2 | J608: =SUMIFS('Overtime Records'!D:D,'Overtime Records'!C:C,'Summary Report'!A608,'Overtime Records'!B:B,'Summary Report'!C608) -> 0 | K608: =J608*G608 -> 0 | L608: =I608/H608 -> 0.090909091
A609: 6 | B609: Michael Washington | C609: ='data dictionary'!$B$4 -> 2025-09 | D609: Machining | E609: Engineer | F609: 3331 | G609: 31.23 | H609: ='data dictionary'!C$4 -> 22 | I609: =SUMIFS('Attendance records'!F:F,'Attendance records'!C:C,'Summary Report'!A609,'Attendance records'!B:B,'Summary Report'!C609) -> 2 | J609: =SUMIFS('Overtime Records'!D:D,'Overtime Records'!C:C,'Summary Report'!A609,'Overtime Records'!B:B,'Summary Report'!C609) -> 9.6 | K609: =J609*G609 -> 299.808 | L609: =I609/H609 -> 0.090909091
A610: 7 | B610: James Carroll | C610: ='data dictionary'!$B$4 -> 2025-09 | D610: Quality | E610: Operator | F610: 2945 | G610: 27.61 | H610: ='data dictionary'!C$4 -> 22 | I610: =SUMIFS('Attendance records'!F:F,'Attendance records'!C:C,'Summary Report'!A610,'Attendance records'!B:B,'Summary Report'!C610) -> 0 | J610: =SUMIFS('Overtime Records'!D:D,'Overtime Records'!C:C,'Summary Report'!A610,'Overtime Records'!B:B,'Summary Report'!C610) -> 4.2 | K610: =J610*G610 -> 115.962 | L610: =I610/H610 -> 0
A611: 8 | B611: Angela Newton DVM | C611: ='data dictionary'!$B$4 -> 2025-09 | D611: Quality | E611: Supervisor | F611: 2259 | G611: 21.18 | H611: ='data dictionary'!C$4 -> 22 | I611: =SUMIFS('Attendance records'!F:F,'Attendance records'!C:C,'Summary Report'!A611,'Attendance records'!B:B,'Summary Report'!C611) -> 1 | J611: =SUMIFS('Overtime Records'!D:D,'Overtime Records'!C:C,'Summary Report'!A611,'Overtime Records'!B:B,'Summary Report'!C611) -> 4.5 | K611: =J611*G611 -> 95.31 | L611: =I611/H611 -> 0.045454545
A612: 9 | B612: Daniel Guzman | C612: ='data dictionary'!$B$4 -> 2025-09 | D612: Quality | E612: Operator | F612: 2275 | G612: 21.33 | H612: ='data dictionary'!C$4 -> 22 | I612: =SUMIFS('Attendance records'!F:F,'Attendance records'!C:C,'Summary Report'!A612,'Attendance records'!B:B,'Summary Report'!C612) -> 1 | J612: =SUMIFS('Overtime Records'!D:D,'Overtime Records'!C:C,'Summary Report'!A612,'Overtime Records'!B:B,'Summary Report'!C612) -> 3.5 | K612: =J612*G612 -> 74.655 | L612: =I612/H612 -> 0.045454545
A613: 10 | B613: Sarah Weber | C613: ='data dictionary'!$B$4 -> 2025-09 | D613: Assembly | E613: Operator | F613: 2344 | G613: 21.98 | H613: ='data dictionary'!C$4 -> 22 | I613: =SUMIFS('Attendance records'!F:F,'Attendance records'!C:C,'Summary Report'!A613,'Attendance records'!B:B,'Summary Report'!C613) -> 3 | J613: =SUMIFS('Overtime Records'!D:D,'Overtime Records'!C:C,'Summary Report'!A613,'Overtime Records'!B:B,'Summary Report'!C613) -> 17.7 | K613: =J613*G613 -> 389.046 | L613: =I613/H613 -> 0.13636364
A614: 11 | B614: Stacy Wells | C614: ='data dictionary'!$B$4 -> 2025-09 | D614: Welding | E614: Engineer | F614: 3935 | G614: 36.89 | H614: ='data dictionary'!C$4 -> 22 | I614: =SUMIFS('Attendance records'!F:F,'Attendance records'!C:C,'Summary Report'!A614,'Attendance records'!B:B,'Summary Report'!C614) -> 2 | J614: =SUMIFS('Overtime Records'!D:D,'Overtime Records'!C:C,'Summary Report'!A614,'Overtime Records'!B:B,'Summary Report'!C614) -> 10.1 | K614: =J614*G614 -> 372.589 | L614: =I614/H614 -> 0.090909091
A615: 12 | B615: Kristen Marsh | C615: ='data dictionary'!$B$4 -> 2025-09 | D615: Welding | E615: Technician | F615: 3394 | G615: 31.82 | H615: ='data dictionary'!C$4 -> 22 | I615: =SUMIFS('Attendance records'!F:F,'Attendance records'!C:C,'Summary Report'!A615,'Attendance records'!B:B,'Summary Report'!C615) -> 3 | J615: =SUMIFS('Overtime Records'!D:D,'Overtime Records'!C:C,'Summary Report'!A615,'Overtime Records'!B:B,'Summary Report'!C615) -> 7.6 | K615: =J615*G615 -> 241.832 | L615: =I615/H615 -> 0.13636364
... A903: 300 | B903: James Simpson | C903: ='data dictionary'!$B$4 -> 2025-09 | D903: Quality | E903: Inspector | F903: 3113 | G903: 29.18 | H903: ='data dictionary'!C$4 -> 22 | I903: =SUMIFS('Attendance records'!F:F,'Attendance records'!C:C,'Summary Report'!A903,'Attendance records'!B:B,'Summary Report'!C903) -> 3 | J903: =SUMIFS('Overtime Records'!D:D,'Overtime Records'!C:C,'Summary Report'!A903,'Overtime Records'!B:B,'Summary Report'!C903) -> 0 | K903: =J903*G903 -> 0 | L903: =I903/H903 -> 0.13636364
...

Sheet data dictionary
A1: Date | B1: Date(month) | C1: Scheduled days
A2: 45839 | B2: =TEXT(A2,"yyyy-mm") -> 2025-07 | C2: 23
A3: 45870 | B3: =TEXT(A3,"yyyy-mm") -> 2025-08 | C3: 21
A4: 45901 | B4: =TEXT(A4,"yyyy-mm") -> 2025-09 | C4: 22
A5: 45931 | B5: =TEXT(A5,"yyyy-mm") -> 2025-10 | C5: 23
A6: 45962 | B6: =TEXT(A6,"yyyy-mm") -> 2025-11 | C6: 20
A7: 45992 | B7: =TEXT(A7,"yyyy-mm") -> 2025-12 | C7: --
